[2025-06-08T16:25:35.363+0000] {taskinstance.py:1956} INFO - Dependencies all met for dep_context=non-requeueable deps ti=<TaskInstance: bento_api_pipeline.bento_train manual__2025-06-08T16:25:34.301412+00:00 [queued]>
[2025-06-08T16:25:35.370+0000] {taskinstance.py:1956} INFO - Dependencies all met for dep_context=requeueable deps ti=<TaskInstance: bento_api_pipeline.bento_train manual__2025-06-08T16:25:34.301412+00:00 [queued]>
[2025-06-08T16:25:35.371+0000] {taskinstance.py:2170} INFO - Starting attempt 1 of 3
[2025-06-08T16:25:35.383+0000] {taskinstance.py:2191} INFO - Executing <Task(PythonOperator): bento_train> on 2025-06-08 16:25:34.301412+00:00
[2025-06-08T16:25:35.389+0000] {standard_task_runner.py:60} INFO - Started process 221 to run task
[2025-06-08T16:25:35.393+0000] {standard_task_runner.py:87} INFO - Running: ['***', 'tasks', 'run', 'bento_api_pipeline', 'bento_train', 'manual__2025-06-08T16:25:34.301412+00:00', '--job-id', '3299', '--raw', '--subdir', 'DAGS_FOLDER/bento_api_pipeline.py', '--cfg-path', '/tmp/tmpvc37avk0']
[2025-06-08T16:25:35.395+0000] {standard_task_runner.py:88} INFO - Job 3299: Subtask bento_train
[2025-06-08T16:25:35.443+0000] {task_command.py:423} INFO - Running <TaskInstance: bento_api_pipeline.bento_train manual__2025-06-08T16:25:34.301412+00:00 [running]> on host 346204e0b744
[2025-06-08T16:25:35.516+0000] {taskinstance.py:2480} INFO - Exporting env vars: AIRFLOW_CTX_DAG_OWNER='***' AIRFLOW_CTX_DAG_ID='bento_api_pipeline' AIRFLOW_CTX_TASK_ID='bento_train' AIRFLOW_CTX_EXECUTION_DATE='2025-06-08T16:25:34.301412+00:00' AIRFLOW_CTX_TRY_NUMBER='1' AIRFLOW_CTX_DAG_RUN_ID='manual__2025-06-08T16:25:34.301412+00:00'
[2025-06-08T16:25:35.537+0000] {bento_api_pipeline.py:27} INFO - BentoML-Training API Response: 500 "An error has occurred in BentoML user code when handling this request, find the error details in server logs"
[2025-06-08T16:25:35.538+0000] {bento_api_pipeline.py:20} INFO - BentoML [TRAIN] RAW RESPONSE:
An error has occurred in BentoML user code when handling this request, find the error details in server logs
[2025-06-08T16:25:35.538+0000] {bento_api_pipeline.py:34} ERROR - Fehler im Training-Call: BentoML Training Error: An error has occurred in BentoML user code when handling this request, find the error details in server logs
[2025-06-08T16:25:35.539+0000] {taskinstance.py:2698} ERROR - Task failed with exception
Traceback (most recent call last):
  File "/home/airflow/.local/lib/python3.10/site-packages/airflow/models/taskinstance.py", line 433, in _execute_task
    result = execute_callable(context=context, **execute_callable_kwargs)
  File "/home/airflow/.local/lib/python3.10/site-packages/airflow/operators/python.py", line 199, in execute
    return_value = self.execute_callable()
  File "/home/airflow/.local/lib/python3.10/site-packages/airflow/operators/python.py", line 216, in execute_callable
    return self.python_callable(*self.op_args, **self.op_kwargs)
  File "/opt/airflow/dags/bento_api_pipeline.py", line 31, in trigger_bento_training
    raise Exception(f"BentoML Training Error: {resp_json}")
Exception: BentoML Training Error: An error has occurred in BentoML user code when handling this request, find the error details in server logs
[2025-06-08T16:25:35.550+0000] {taskinstance.py:1138} INFO - Marking task as UP_FOR_RETRY. dag_id=bento_api_pipeline, task_id=bento_train, execution_date=20250608T162534, start_date=20250608T162535, end_date=20250608T162535
[2025-06-08T16:25:35.561+0000] {standard_task_runner.py:107} ERROR - Failed to execute job 3299 for task bento_train (BentoML Training Error: An error has occurred in BentoML user code when handling this request, find the error details in server logs; 221)
[2025-06-08T16:25:35.604+0000] {local_task_job_runner.py:234} INFO - Task exited with return code 1
[2025-06-08T16:25:35.626+0000] {taskinstance.py:3280} INFO - 0 downstream tasks scheduled from follow-on schedule check
