[2025-06-01T16:14:48.382+0000] {taskinstance.py:1956} INFO - Dependencies all met for dep_context=non-requeueable deps ti=<TaskInstance: movie_recommendation_pipeline.validate_models manual__2025-06-01T16:13:03.362156+00:00 [queued]>
[2025-06-01T16:14:48.389+0000] {taskinstance.py:1956} INFO - Dependencies all met for dep_context=requeueable deps ti=<TaskInstance: movie_recommendation_pipeline.validate_models manual__2025-06-01T16:13:03.362156+00:00 [queued]>
[2025-06-01T16:14:48.390+0000] {taskinstance.py:2170} INFO - Starting attempt 1 of 3
[2025-06-01T16:14:48.402+0000] {taskinstance.py:2191} INFO - Executing <Task(PythonOperator): validate_models> on 2025-06-01 16:13:03.362156+00:00
[2025-06-01T16:14:48.409+0000] {standard_task_runner.py:60} INFO - Started process 495 to run task
[2025-06-01T16:14:48.411+0000] {standard_task_runner.py:87} INFO - Running: ['***', 'tasks', 'run', 'movie_recommendation_pipeline', 'validate_models', 'manual__2025-06-01T16:13:03.362156+00:00', '--job-id', '1144', '--raw', '--subdir', 'DAGS_FOLDER/mlops_movie_dag.py', '--cfg-path', '/tmp/tmpfr1xmni7']
[2025-06-01T16:14:48.413+0000] {standard_task_runner.py:88} INFO - Job 1144: Subtask validate_models
[2025-06-01T16:14:48.450+0000] {task_command.py:423} INFO - Running <TaskInstance: movie_recommendation_pipeline.validate_models manual__2025-06-01T16:13:03.362156+00:00 [running]> on host 9269b0e4c044
[2025-06-01T16:14:48.508+0000] {taskinstance.py:2480} INFO - Exporting env vars: AIRFLOW_CTX_DAG_OWNER='***' AIRFLOW_CTX_DAG_ID='movie_recommendation_pipeline' AIRFLOW_CTX_TASK_ID='validate_models' AIRFLOW_CTX_EXECUTION_DATE='2025-06-01T16:13:03.362156+00:00' AIRFLOW_CTX_TRY_NUMBER='1' AIRFLOW_CTX_DAG_RUN_ID='manual__2025-06-01T16:13:03.362156+00:00'
[2025-06-01T16:14:50.573+0000] {mlops_movie_dag.py:13} INFO - 2025-06-01 16:14:49,469 - INFO - ðŸš€ Starte Validierung der Modelle aus MLflow & DVC
Traceback (most recent call last):
  File "/home/***/.local/lib/python3.10/site-packages/pandas/core/indexes/base.py", line 3802, in get_loc
    return self._engine.get_loc(casted_key)
  File "pandas/_libs/index.pyx", line 138, in pandas._libs.index.IndexEngine.get_loc
  File "pandas/_libs/index.pyx", line 165, in pandas._libs.index.IndexEngine.get_loc
  File "pandas/_libs/hashtable_class_helper.pxi", line 5745, in pandas._libs.hashtable.PyObjectHashTable.get_item
  File "pandas/_libs/hashtable_class_helper.pxi", line 5753, in pandas._libs.hashtable.PyObjectHashTable.get_item
KeyError: 'metrics.precision_10'

The above exception was the direct cause of the following exception:

Traceback (most recent call last):
  File "/opt/***/src/models/validate_model.py", line 69, in <module>
    validate_models()
  File "/opt/***/src/models/validate_model.py", line 39, in validate_models
    best_user = get_best_model_info(runs_user, "user")
  File "/opt/***/src/models/validate_model.py", line 30, in get_best_model_info
    runs["metrics.precision_10"] = pd.to_numeric(runs["metrics.precision_10"], errors="coerce")
  File "/home/***/.local/lib/python3.10/site-packages/pandas/core/frame.py", line 3807, in __getitem__
    indexer = self.columns.get_loc(key)
  File "/home/***/.local/lib/python3.10/site-packages/pandas/core/indexes/base.py", line 3804, in get_loc
    raise KeyError(key) from err
KeyError: 'metrics.precision_10'

[2025-06-01T16:14:50.574+0000] {python.py:201} INFO - Done. Returned value was: None
[2025-06-01T16:14:50.584+0000] {taskinstance.py:1138} INFO - Marking task as SUCCESS. dag_id=movie_recommendation_pipeline, task_id=validate_models, execution_date=20250601T161303, start_date=20250601T161448, end_date=20250601T161450
[2025-06-01T16:14:50.631+0000] {local_task_job_runner.py:234} INFO - Task exited with return code 0
[2025-06-01T16:14:50.647+0000] {taskinstance.py:3280} INFO - 1 downstream tasks scheduled from follow-on schedule check
