[2025-06-02T10:14:40.667+0000] {taskinstance.py:1956} INFO - Dependencies all met for dep_context=non-requeueable deps ti=<TaskInstance: movie_recommendation_pipeline.validate_models manual__2025-06-02T10:04:11.335787+00:00 [queued]>
[2025-06-02T10:14:40.675+0000] {taskinstance.py:1956} INFO - Dependencies all met for dep_context=requeueable deps ti=<TaskInstance: movie_recommendation_pipeline.validate_models manual__2025-06-02T10:04:11.335787+00:00 [queued]>
[2025-06-02T10:14:40.675+0000] {taskinstance.py:2170} INFO - Starting attempt 2 of 3
[2025-06-02T10:14:40.686+0000] {taskinstance.py:2191} INFO - Executing <Task(PythonOperator): validate_models> on 2025-06-02 10:04:11.335787+00:00
[2025-06-02T10:14:40.693+0000] {standard_task_runner.py:60} INFO - Started process 1291 to run task
[2025-06-02T10:14:40.695+0000] {standard_task_runner.py:87} INFO - Running: ['***', 'tasks', 'run', 'movie_recommendation_pipeline', 'validate_models', 'manual__2025-06-02T10:04:11.335787+00:00', '--job-id', '1661', '--raw', '--subdir', 'DAGS_FOLDER/mlops_movie_dag.py', '--cfg-path', '/tmp/tmph3p4ltnm']
[2025-06-02T10:14:40.696+0000] {standard_task_runner.py:88} INFO - Job 1661: Subtask validate_models
[2025-06-02T10:14:40.728+0000] {task_command.py:423} INFO - Running <TaskInstance: movie_recommendation_pipeline.validate_models manual__2025-06-02T10:04:11.335787+00:00 [running]> on host 43a492dd7637
[2025-06-02T10:14:40.785+0000] {taskinstance.py:2480} INFO - Exporting env vars: AIRFLOW_CTX_DAG_OWNER='***' AIRFLOW_CTX_DAG_ID='movie_recommendation_pipeline' AIRFLOW_CTX_TASK_ID='validate_models' AIRFLOW_CTX_EXECUTION_DATE='2025-06-02T10:04:11.335787+00:00' AIRFLOW_CTX_TRY_NUMBER='2' AIRFLOW_CTX_DAG_RUN_ID='manual__2025-06-02T10:04:11.335787+00:00'
[2025-06-02T10:14:40.785+0000] {mlops_movie_dag.py:12} INFO - üü¶ Running command: python /opt/***/src/models/validate_model.py --test_user_count=107 --test_user_seed=42
[2025-06-02T10:14:42.713+0000] {mlops_movie_dag.py:19} INFO - üü© [stdout]:

[2025-06-02T10:14:42.714+0000] {mlops_movie_dag.py:21} WARNING - üü® [stderr]:
usage: validate_model.py [-h] [--test_user_count TEST_USER_COUNT]
validate_model.py: error: unrecognized arguments: --test_user_seed=42

[2025-06-02T10:14:42.715+0000] {mlops_movie_dag.py:28} ERROR - ‚ùå Subprozess-Fehler (exit code 2): python /opt/***/src/models/validate_model.py --test_user_count=107 --test_user_seed=42
[2025-06-02T10:14:42.715+0000] {mlops_movie_dag.py:31} ERROR - ‚ùå Subprozess-Ausnahme: Command '['python', '/opt/***/src/models/validate_model.py', '--test_user_count=107', '--test_user_seed=42']' returned non-zero exit status 2.
[2025-06-02T10:14:42.716+0000] {taskinstance.py:2698} ERROR - Task failed with exception
Traceback (most recent call last):
  File "/home/airflow/.local/lib/python3.10/site-packages/airflow/models/taskinstance.py", line 433, in _execute_task
    result = execute_callable(context=context, **execute_callable_kwargs)
  File "/home/airflow/.local/lib/python3.10/site-packages/airflow/operators/python.py", line 199, in execute
    return_value = self.execute_callable()
  File "/home/airflow/.local/lib/python3.10/site-packages/airflow/operators/python.py", line 216, in execute_callable
    return self.python_callable(*self.op_args, **self.op_kwargs)
  File "/opt/airflow/dags/mlops_movie_dag.py", line 52, in run_validate_models
    run_and_log([
  File "/opt/airflow/dags/mlops_movie_dag.py", line 29, in run_and_log
    raise subprocess.CalledProcessError(result.returncode, command)
subprocess.CalledProcessError: Command '['python', '/opt/airflow/src/models/validate_model.py', '--test_user_count=107', '--test_user_seed=42']' returned non-zero exit status 2.
[2025-06-02T10:14:42.725+0000] {taskinstance.py:1138} INFO - Marking task as UP_FOR_RETRY. dag_id=movie_recommendation_pipeline, task_id=validate_models, execution_date=20250602T100411, start_date=20250602T101440, end_date=20250602T101442
[2025-06-02T10:14:42.737+0000] {standard_task_runner.py:107} ERROR - Failed to execute job 1661 for task validate_models (Command '['python', '/opt/airflow/src/models/validate_model.py', '--test_user_count=107', '--test_user_seed=42']' returned non-zero exit status 2.; 1291)
[2025-06-02T10:14:42.754+0000] {local_task_job_runner.py:234} INFO - Task exited with return code 1
[2025-06-02T10:14:42.771+0000] {taskinstance.py:3280} INFO - 0 downstream tasks scheduled from follow-on schedule check
