[2025-06-01T10:38:01.593+0000] {taskinstance.py:1956} INFO - Dependencies all met for dep_context=non-requeueable deps ti=<TaskInstance: movie_recommendation_pipeline.validate_models manual__2025-06-01T10:32:33.819204+00:00 [queued]>
[2025-06-01T10:38:01.599+0000] {taskinstance.py:1956} INFO - Dependencies all met for dep_context=requeueable deps ti=<TaskInstance: movie_recommendation_pipeline.validate_models manual__2025-06-01T10:32:33.819204+00:00 [queued]>
[2025-06-01T10:38:01.600+0000] {taskinstance.py:2170} INFO - Starting attempt 1 of 3
[2025-06-01T10:38:01.610+0000] {taskinstance.py:2191} INFO - Executing <Task(PythonOperator): validate_models> on 2025-06-01 10:32:33.819204+00:00
[2025-06-01T10:38:01.616+0000] {standard_task_runner.py:60} INFO - Started process 733 to run task
[2025-06-01T10:38:01.618+0000] {standard_task_runner.py:87} INFO - Running: ['***', 'tasks', 'run', 'movie_recommendation_pipeline', 'validate_models', 'manual__2025-06-01T10:32:33.819204+00:00', '--job-id', '952', '--raw', '--subdir', 'DAGS_FOLDER/mlops_movie_dag.py', '--cfg-path', '/tmp/tmpf3d8o5a4']
[2025-06-01T10:38:01.619+0000] {standard_task_runner.py:88} INFO - Job 952: Subtask validate_models
[2025-06-01T10:38:01.651+0000] {task_command.py:423} INFO - Running <TaskInstance: movie_recommendation_pipeline.validate_models manual__2025-06-01T10:32:33.819204+00:00 [running]> on host 9de233c7eb3e
[2025-06-01T10:38:01.704+0000] {taskinstance.py:2480} INFO - Exporting env vars: AIRFLOW_CTX_DAG_OWNER='***' AIRFLOW_CTX_DAG_ID='movie_recommendation_pipeline' AIRFLOW_CTX_TASK_ID='validate_models' AIRFLOW_CTX_EXECUTION_DATE='2025-06-01T10:32:33.819204+00:00' AIRFLOW_CTX_TRY_NUMBER='1' AIRFLOW_CTX_DAG_RUN_ID='manual__2025-06-01T10:32:33.819204+00:00'
[2025-06-01T10:40:27.454+0000] {local_task_job_runner.py:121} ERROR - Received SIGTERM. Terminating subprocesses
[2025-06-01T10:40:27.468+0000] {process_utils.py:131} INFO - Sending 15 to group 733. PIDs of all processes in the group: [734, 733]
[2025-06-01T10:40:27.469+0000] {process_utils.py:86} INFO - Sending the signal 15 to group 733
[2025-06-01T10:40:27.471+0000] {taskinstance.py:2450} ERROR - Received SIGTERM. Terminating subprocesses.
[2025-06-01T10:40:27.499+0000] {process_utils.py:79} INFO - Process psutil.Process(pid=734, status='terminated', started='10:38:00') (734) terminated with exit code None
[2025-06-01T10:40:27.498+0000] {taskinstance.py:2698} ERROR - Task failed with exception
Traceback (most recent call last):
  File "/home/airflow/.local/lib/python3.10/site-packages/airflow/models/taskinstance.py", line 433, in _execute_task
    result = execute_callable(context=context, **execute_callable_kwargs)
  File "/home/airflow/.local/lib/python3.10/site-packages/airflow/operators/python.py", line 199, in execute
    return_value = self.execute_callable()
  File "/home/airflow/.local/lib/python3.10/site-packages/airflow/operators/python.py", line 216, in execute_callable
    return self.python_callable(*self.op_args, **self.op_kwargs)
  File "/opt/airflow/dags/mlops_movie_dag.py", line 35, in run_validate_models
    run_and_log(["python", "/opt/airflow/src/models/validate_model.py"])
  File "/opt/airflow/dags/mlops_movie_dag.py", line 12, in run_and_log
    result = subprocess.run(command, stdout=subprocess.PIPE, stderr=subprocess.STDOUT, text=True)
  File "/usr/local/lib/python3.10/subprocess.py", line 505, in run
    stdout, stderr = process.communicate(input, timeout=timeout)
  File "/usr/local/lib/python3.10/subprocess.py", line 1141, in communicate
    stdout = self.stdout.read()
  File "/home/airflow/.local/lib/python3.10/site-packages/airflow/models/taskinstance.py", line 2452, in signal_handler
    raise AirflowException("Task received SIGTERM signal")
airflow.exceptions.AirflowException: Task received SIGTERM signal
[2025-06-01T10:40:27.505+0000] {taskinstance.py:1138} INFO - Marking task as UP_FOR_RETRY. dag_id=movie_recommendation_pipeline, task_id=validate_models, execution_date=20250601T103233, start_date=20250601T103801, end_date=20250601T104027
[2025-06-01T10:40:27.515+0000] {standard_task_runner.py:107} ERROR - Failed to execute job 952 for task validate_models (Task received SIGTERM signal; 733)
[2025-06-01T10:40:27.526+0000] {process_utils.py:79} INFO - Process psutil.Process(pid=733, status='terminated', exitcode=1, started='10:38:00') (733) terminated with exit code 1
[2025-06-01T10:40:27.527+0000] {local_task_job_runner.py:234} INFO - Task exited with return code 143
[2025-06-01T10:40:27.545+0000] {taskinstance.py:3280} INFO - 0 downstream tasks scheduled from follow-on schedule check
