[2025-06-07T21:58:20.522+0000] {taskinstance.py:1956} INFO - Dependencies all met for dep_context=non-requeueable deps ti=<TaskInstance: deep_models_pipeline.predict_best_model manual__2025-06-07T21:58:19.926333+00:00 [queued]>
[2025-06-07T21:58:20.529+0000] {taskinstance.py:1956} INFO - Dependencies all met for dep_context=requeueable deps ti=<TaskInstance: deep_models_pipeline.predict_best_model manual__2025-06-07T21:58:19.926333+00:00 [queued]>
[2025-06-07T21:58:20.530+0000] {taskinstance.py:2170} INFO - Starting attempt 1 of 3
[2025-06-07T21:58:20.544+0000] {taskinstance.py:2191} INFO - Executing <Task(PythonOperator): predict_best_model> on 2025-06-07 21:58:19.926333+00:00
[2025-06-07T21:58:20.551+0000] {standard_task_runner.py:60} INFO - Started process 2270 to run task
[2025-06-07T21:58:20.563+0000] {standard_task_runner.py:87} INFO - Running: ['***', 'tasks', 'run', 'deep_models_pipeline', 'predict_best_model', 'manual__2025-06-07T21:58:19.926333+00:00', '--job-id', '2731', '--raw', '--subdir', 'DAGS_FOLDER/train_deep_model_dag.py', '--cfg-path', '/tmp/tmp4sd07aoz']
[2025-06-07T21:58:20.565+0000] {standard_task_runner.py:88} INFO - Job 2731: Subtask predict_best_model
[2025-06-07T21:58:20.615+0000] {task_command.py:423} INFO - Running <TaskInstance: deep_models_pipeline.predict_best_model manual__2025-06-07T21:58:19.926333+00:00 [running]> on host a47caab93d5d
[2025-06-07T21:58:20.691+0000] {taskinstance.py:2480} INFO - Exporting env vars: AIRFLOW_CTX_DAG_OWNER='***' AIRFLOW_CTX_DAG_ID='deep_models_pipeline' AIRFLOW_CTX_TASK_ID='predict_best_model' AIRFLOW_CTX_EXECUTION_DATE='2025-06-07T21:58:19.926333+00:00' AIRFLOW_CTX_TRY_NUMBER='1' AIRFLOW_CTX_DAG_RUN_ID='manual__2025-06-07T21:58:19.926333+00:00'
[2025-06-07T21:58:20.693+0000] {train_deep_model_dag.py:13} INFO - üü¶ Running command: python /opt/***/src/models/predict_best_model.py
[2025-06-07T21:58:52.510+0000] {local_task_job_runner.py:121} ERROR - Received SIGTERM. Terminating subprocesses
[2025-06-07T21:58:52.515+0000] {process_utils.py:131} INFO - Sending 15 to group 2270. PIDs of all processes in the group: [2277, 2270]
[2025-06-07T21:58:52.516+0000] {process_utils.py:86} INFO - Sending the signal 15 to group 2270
[2025-06-07T21:58:52.518+0000] {taskinstance.py:2450} ERROR - Received SIGTERM. Terminating subprocesses.
[2025-06-07T21:58:52.544+0000] {train_deep_model_dag.py:32} ERROR - ‚ùå Subprozess-Ausnahme: Task received SIGTERM signal
[2025-06-07T21:58:52.545+0000] {process_utils.py:79} INFO - Process psutil.Process(pid=2277, status='terminated', started='21:58:20') (2277) terminated with exit code None
[2025-06-07T21:58:52.558+0000] {taskinstance.py:2698} ERROR - Task failed with exception
Traceback (most recent call last):
  File "/home/airflow/.local/lib/python3.10/site-packages/airflow/models/taskinstance.py", line 433, in _execute_task
    result = execute_callable(context=context, **execute_callable_kwargs)
  File "/home/airflow/.local/lib/python3.10/site-packages/airflow/operators/python.py", line 199, in execute
    return_value = self.execute_callable()
  File "/home/airflow/.local/lib/python3.10/site-packages/airflow/operators/python.py", line 216, in execute_callable
    return self.python_callable(*self.op_args, **self.op_kwargs)
  File "/opt/airflow/dags/train_deep_model_dag.py", line 71, in run_predict_best_model
    run_and_log(["python", "/opt/airflow/src/models/predict_best_model.py"])
  File "/opt/airflow/dags/train_deep_model_dag.py", line 14, in run_and_log
    result = subprocess.run(
  File "/usr/local/lib/python3.10/subprocess.py", line 505, in run
    stdout, stderr = process.communicate(input, timeout=timeout)
  File "/usr/local/lib/python3.10/subprocess.py", line 1154, in communicate
    stdout, stderr = self._communicate(input, endtime, timeout)
  File "/usr/local/lib/python3.10/subprocess.py", line 2021, in _communicate
    ready = selector.select(timeout)
  File "/usr/local/lib/python3.10/selectors.py", line 416, in select
    fd_event_list = self._selector.poll(timeout)
  File "/home/airflow/.local/lib/python3.10/site-packages/airflow/models/taskinstance.py", line 2452, in signal_handler
    raise AirflowException("Task received SIGTERM signal")
airflow.exceptions.AirflowException: Task received SIGTERM signal
[2025-06-07T21:58:52.566+0000] {taskinstance.py:1138} INFO - Marking task as UP_FOR_RETRY. dag_id=deep_models_pipeline, task_id=predict_best_model, execution_date=20250607T215819, start_date=20250607T215820, end_date=20250607T215852
[2025-06-07T21:58:52.585+0000] {standard_task_runner.py:107} ERROR - Failed to execute job 2731 for task predict_best_model (Task received SIGTERM signal; 2270)
[2025-06-07T21:58:52.598+0000] {process_utils.py:79} INFO - Process psutil.Process(pid=2270, status='terminated', exitcode=1, started='21:58:20') (2270) terminated with exit code 1
[2025-06-07T21:58:52.600+0000] {local_task_job_runner.py:234} INFO - Task exited with return code 143
[2025-06-07T21:58:52.618+0000] {taskinstance.py:3280} INFO - 0 downstream tasks scheduled from follow-on schedule check
