[2025-06-01T20:37:55.979+0000] {taskinstance.py:1956} INFO - Dependencies all met for dep_context=non-requeueable deps ti=<TaskInstance: movie_recommendation_pipeline.validate_models manual__2025-06-01T20:29:34.732345+00:00 [queued]>
[2025-06-01T20:37:55.987+0000] {taskinstance.py:1956} INFO - Dependencies all met for dep_context=requeueable deps ti=<TaskInstance: movie_recommendation_pipeline.validate_models manual__2025-06-01T20:29:34.732345+00:00 [queued]>
[2025-06-01T20:37:55.988+0000] {taskinstance.py:2170} INFO - Starting attempt 1 of 3
[2025-06-01T20:37:55.999+0000] {taskinstance.py:2191} INFO - Executing <Task(PythonOperator): validate_models> on 2025-06-01 20:29:34.732345+00:00
[2025-06-01T20:37:56.003+0000] {standard_task_runner.py:60} INFO - Started process 1279 to run task
[2025-06-01T20:37:56.005+0000] {standard_task_runner.py:87} INFO - Running: ['***', 'tasks', 'run', 'movie_recommendation_pipeline', 'validate_models', 'manual__2025-06-01T20:29:34.732345+00:00', '--job-id', '1264', '--raw', '--subdir', 'DAGS_FOLDER/mlops_movie_dag.py', '--cfg-path', '/tmp/tmp35tc2j41']
[2025-06-01T20:37:56.006+0000] {standard_task_runner.py:88} INFO - Job 1264: Subtask validate_models
[2025-06-01T20:37:56.037+0000] {task_command.py:423} INFO - Running <TaskInstance: movie_recommendation_pipeline.validate_models manual__2025-06-01T20:29:34.732345+00:00 [running]> on host 232dd595ceb7
[2025-06-01T20:37:56.096+0000] {taskinstance.py:2480} INFO - Exporting env vars: AIRFLOW_CTX_DAG_OWNER='***' AIRFLOW_CTX_DAG_ID='movie_recommendation_pipeline' AIRFLOW_CTX_TASK_ID='validate_models' AIRFLOW_CTX_EXECUTION_DATE='2025-06-01T20:29:34.732345+00:00' AIRFLOW_CTX_TRY_NUMBER='1' AIRFLOW_CTX_DAG_RUN_ID='manual__2025-06-01T20:29:34.732345+00:00'
[2025-06-01T20:37:56.097+0000] {mlops_movie_dag.py:12} INFO - üü¶ Running command: python /opt/***/src/models/validate_model.py
[2025-06-01T20:38:00.955+0000] {mlops_movie_dag.py:18} INFO - üü© [stdout]:

[2025-06-01T20:38:00.956+0000] {mlops_movie_dag.py:20} WARNING - üü® [stderr]:
2025-06-01 20:37:57,837 - INFO - üöÄ Starte Validierung der Modelle
ERROR: failed to pull data from the cloud - Unable to acquire lock. Most likely another DVC process is running or was terminated abruptly. Check the page <https://dvc.org/doc/user-guide/troubleshooting#lock-issue> for other possible reasons and to learn how to resolve this.
2025-06-01 20:38:00,716 - ERROR - ‚ùå Fehler bei DVC Pull f√ºr /opt/***/models/hybrid_model.pkl: Command '['dvc', 'pull', '/opt/***/models/hybrid_model.pkl']' returned non-zero exit status 1.
2025-06-01 20:38:00,716 - ERROR - ‚ùå Konnte Modelle nicht von DVC holen!

[2025-06-01T20:38:00.957+0000] {python.py:201} INFO - Done. Returned value was: None
[2025-06-01T20:38:00.965+0000] {taskinstance.py:1138} INFO - Marking task as SUCCESS. dag_id=movie_recommendation_pipeline, task_id=validate_models, execution_date=20250601T202934, start_date=20250601T203755, end_date=20250601T203800
[2025-06-01T20:38:00.993+0000] {local_task_job_runner.py:234} INFO - Task exited with return code 0
[2025-06-01T20:38:01.010+0000] {taskinstance.py:3280} INFO - 1 downstream tasks scheduled from follow-on schedule check
