[2025-06-06T15:44:27.791+0000] {taskinstance.py:1956} INFO - Dependencies all met for dep_context=non-requeueable deps ti=<TaskInstance: deep_models_pipeline.predict_best_model manual__2025-06-06T15:41:08.809410+00:00 [queued]>
[2025-06-06T15:44:27.802+0000] {taskinstance.py:1956} INFO - Dependencies all met for dep_context=requeueable deps ti=<TaskInstance: deep_models_pipeline.predict_best_model manual__2025-06-06T15:41:08.809410+00:00 [queued]>
[2025-06-06T15:44:27.802+0000] {taskinstance.py:2170} INFO - Starting attempt 2 of 3
[2025-06-06T15:44:27.814+0000] {taskinstance.py:2191} INFO - Executing <Task(PythonOperator): predict_best_model> on 2025-06-06 15:41:08.809410+00:00
[2025-06-06T15:44:27.821+0000] {standard_task_runner.py:60} INFO - Started process 778 to run task
[2025-06-06T15:44:27.823+0000] {standard_task_runner.py:87} INFO - Running: ['***', 'tasks', 'run', 'deep_models_pipeline', 'predict_best_model', 'manual__2025-06-06T15:41:08.809410+00:00', '--job-id', '2197', '--raw', '--subdir', 'DAGS_FOLDER/train_deep_model_dag.py', '--cfg-path', '/tmp/tmpcf18nyrp']
[2025-06-06T15:44:27.825+0000] {standard_task_runner.py:88} INFO - Job 2197: Subtask predict_best_model
[2025-06-06T15:44:27.865+0000] {task_command.py:423} INFO - Running <TaskInstance: deep_models_pipeline.predict_best_model manual__2025-06-06T15:41:08.809410+00:00 [running]> on host 26b7f3e8e752
[2025-06-06T15:44:27.929+0000] {taskinstance.py:2480} INFO - Exporting env vars: AIRFLOW_CTX_DAG_OWNER='***' AIRFLOW_CTX_DAG_ID='deep_models_pipeline' AIRFLOW_CTX_TASK_ID='predict_best_model' AIRFLOW_CTX_EXECUTION_DATE='2025-06-06T15:41:08.809410+00:00' AIRFLOW_CTX_TRY_NUMBER='2' AIRFLOW_CTX_DAG_RUN_ID='manual__2025-06-06T15:41:08.809410+00:00'
[2025-06-06T15:44:27.930+0000] {train_deep_model_dag.py:13} INFO - 🟦 Running command: python /opt/***/src/models/predict_best_model.py
[2025-06-06T15:44:34.884+0000] {train_deep_model_dag.py:20} INFO - 🟩 [stdout]:

[2025-06-06T15:44:34.885+0000] {train_deep_model_dag.py:22} WARNING - 🟨 [stderr]:
2025-06-06 15:44:29,668 - INFO - 🚀 Starte Prediction für hybrid_deep_model über MLflow Registry
2025-06-06 15:44:29,668 - INFO - 📦 Lade Modell: models:/hybrid_deep_model@best_model

Downloading artifacts:   0%|          | 0/8 [00:00<?, ?it/s]
Downloading artifacts:  12%|█▎        | 1/8 [00:00<00:00, 11748.75it/s]
Downloading artifacts:  25%|██▌       | 2/8 [00:00<00:00,  7.74it/s]   
Downloading artifacts:  25%|██▌       | 2/8 [00:00<00:00,  7.74it/s]
Downloading artifacts:  38%|███▊      | 3/8 [00:00<00:00,  8.48it/s]
Downloading artifacts:  38%|███▊      | 3/8 [00:00<00:00,  8.48it/s]
Downloading artifacts:  50%|█████     | 4/8 [00:00<00:00,  8.20it/s]
Downloading artifacts:  50%|█████     | 4/8 [00:00<00:00,  8.20it/s]
Downloading artifacts:  62%|██████▎   | 5/8 [00:01<00:00,  3.85it/s]
Downloading artifacts:  62%|██████▎   | 5/8 [00:01<00:00,  3.85it/s]
Downloading artifacts:  75%|███████▌  | 6/8 [00:01<00:00,  3.85it/s]
Downloading artifacts:  88%|████████▊ | 7/8 [00:01<00:00,  3.99it/s]
Downloading artifacts:  88%|████████▊ | 7/8 [00:01<00:00,  3.99it/s]
Downloading artifacts: 100%|██████████| 8/8 [00:02<00:00,  2.26it/s]
Downloading artifacts: 100%|██████████| 8/8 [00:02<00:00,  2.26it/s]
Downloading artifacts: 100%|██████████| 8/8 [00:02<00:00,  3.23it/s]
2025-06-06 15:44:34,503 - INFO - 📥 Embedding geladen: /opt/***/data/processed/hybrid_deep_embedding.csv – Shape: (10381, 32)
2025-06-06 15:44:34,519 - ERROR - ❌ Fehler bei der Modellvorhersage: Failed to enforce schema of data '           0         1         2  ...        29        30        31
1   0.421580 -0.972963 -0.428596  ... -0.550750 -0.229378  0.093925
2   0.374361 -0.938532 -0.256197  ... -0.029694 -0.189934  0.047831
3   0.239499 -0.298619 -0.074746  ... -0.097347 -0.124955  0.016886
4   0.305357 -0.321334 -0.234206  ... -0.129693 -0.025723  0.166941
5   0.376688 -0.577884 -0.089250  ... -0.099633 -0.131034  0.164333
6  -0.137236 -0.023219  0.081988  ...  0.434681 -0.670493 -0.264662
7   0.280709 -0.405267 -0.246000  ... -0.206492 -0.140180  0.108925
8   0.280578 -0.336007 -0.232926  ... -0.119108 -0.292399 -0.009090
9   0.123992 -0.564759  0.110439  ...  0.128164 -0.349921 -0.081167
10 -0.269818 -0.781912 -0.549111  ... -0.473585 -0.654332  0.261862

[10 rows x 32 columns]' with schema '['emb_0': float (required), 'emb_1': float (required), 'emb_2': float (required), 'emb_3': float (required), 'emb_4': float (required), 'emb_5': float (required), 'emb_6': float (required), 'emb_7': float (required), 'emb_8': float (required), 'emb_9': float (required), 'emb_10': float (required), 'emb_11': float (required), 'emb_12': float (required), 'emb_13': float (required), 'emb_14': float (required), 'emb_15': float (required), 'emb_16': float (required), 'emb_17': float (required), 'emb_18': float (required), 'emb_19': float (required), 'emb_20': float (required), 'emb_21': float (required), 'emb_22': float (required), 'emb_23': float (required), 'emb_24': float (required), 'emb_25': float (required), 'emb_26': float (required), 'emb_27': float (required), 'emb_28': float (required), 'emb_29': float (required), 'emb_30': float (required), 'emb_31': float (required)]'. Error: Model is missing inputs ['emb_0', 'emb_1', 'emb_2', 'emb_3', 'emb_4', 'emb_5', 'emb_6', 'emb_7', 'emb_8', 'emb_9', 'emb_10', 'emb_11', 'emb_12', 'emb_13', 'emb_14', 'emb_15', 'emb_16', 'emb_17', 'emb_18', 'emb_19', 'emb_20', 'emb_21', 'emb_22', 'emb_23', 'emb_24', 'emb_25', 'emb_26', 'emb_27', 'emb_28', 'emb_29', 'emb_30', 'emb_31']. Note that there were extra inputs: ['29', '27', '8', '6', '16', '30', '24', '31', '10', '20', '22', '11', '5', '28', '17', '9', '14', '15', '26', '7', '18', '23', '19', '12', '21', '13', '0', '2', '3', '1', '25', '4']
Traceback (most recent call last):
  File "/home/***/.local/lib/python3.10/site-packages/mlflow/pyfunc/__init__.py", line 730, in _validate_prediction_input
    data = _enforce_schema(data, input_schema, flavor)
  File "/home/***/.local/lib/python3.10/site-packages/mlflow/models/utils.py", line 1259, in _enforce_schema
    raise MlflowException(message)
mlflow.exceptions.MlflowException: Model is missing inputs ['emb_0', 'emb_1', 'emb_2', 'emb_3', 'emb_4', 'emb_5', 'emb_6', 'emb_7', 'emb_8', 'emb_9', 'emb_10', 'emb_11', 'emb_12', 'emb_13', 'emb_14', 'emb_15', 'emb_16', 'emb_17', 'emb_18', 'emb_19', 'emb_20', 'emb_21', 'emb_22', 'emb_23', 'emb_24', 'emb_25', 'emb_26', 'emb_27', 'emb_28', 'emb_29', 'emb_30', 'emb_31']. Note that there were extra inputs: ['29', '27', '8', '6', '16', '30', '24', '31', '10', '20', '22', '11', '5', '28', '17', '9', '14', '15', '26', '7', '18', '23', '19', '12', '21', '13', '0', '2', '3', '1', '25', '4']

During handling of the above exception, another exception occurred:

Traceback (most recent call last):
  File "/opt/***/src/models/predict_best_model.py", line 66, in <module>
    predict_best_model(n_users=args.n_users)
  File "/opt/***/src/models/predict_best_model.py", line 37, in predict_best_model
    predictions = model.predict(input_df)
  File "/home/***/.local/lib/python3.10/site-packages/mlflow/pyfunc/__init__.py", line 812, in predict
    return self._predict(data, params)
  File "/home/***/.local/lib/python3.10/site-packages/mlflow/pyfunc/__init__.py", line 851, in _predict
    data, params = _validate_prediction_input(
  File "/home/***/.local/lib/python3.10/site-packages/mlflow/pyfunc/__init__.py", line 733, in _validate_prediction_input
    raise MlflowException.invalid_parameter_value(
mlflow.exceptions.MlflowException: Failed to enforce schema of data '           0         1         2  ...        29        30        31
1   0.421580 -0.972963 -0.428596  ... -0.550750 -0.229378  0.093925
2   0.374361 -0.938532 -0.256197  ... -0.029694 -0.189934  0.047831
3   0.239499 -0.298619 -0.074746  ... -0.097347 -0.124955  0.016886
4   0.305357 -0.321334 -0.234206  ... -0.129693 -0.025723  0.166941
5   0.376688 -0.577884 -0.089250  ... -0.099633 -0.131034  0.164333
6  -0.137236 -0.023219  0.081988  ...  0.434681 -0.670493 -0.264662
7   0.280709 -0.405267 -0.246000  ... -0.206492 -0.140180  0.108925
8   0.280578 -0.336007 -0.232926  ... -0.119108 -0.292399 -0.009090
9   0.123992 -0.564759  0.110439  ...  0.128164 -0.349921 -0.081167
10 -0.269818 -0.781912 -0.549111  ... -0.473585 -0.654332  0.261862

[10 rows x 32 columns]' with schema '['emb_0': float (required), 'emb_1': float (required), 'emb_2': float (required), 'emb_3': float (required), 'emb_4': float (required), 'emb_5': float (required), 'emb_6': float (required), 'emb_7': float (required), 'emb_8': float (required), 'emb_9': float (required), 'emb_10': float (required), 'emb_11': float (required), 'emb_12': float (required), 'emb_13': float (required), 'emb_14': float (required), 'emb_15': float (required), 'emb_16': float (required), 'emb_17': float (required), 'emb_18': float (required), 'emb_19': float (required), 'emb_20': float (required), 'emb_21': float (required), 'emb_22': float (required), 'emb_23': float (required), 'emb_24': float (required), 'emb_25': float (required), 'emb_26': float (required), 'emb_27': float (required), 'emb_28': float (required), 'emb_29': float (required), 'emb_30': float (required), 'emb_31': float (required)]'. Error: Model is missing inputs ['emb_0', 'emb_1', 'emb_2', 'emb_3', 'emb_4', 'emb_5', 'emb_6', 'emb_7', 'emb_8', 'emb_9', 'emb_10', 'emb_11', 'emb_12', 'emb_13', 'emb_14', 'emb_15', 'emb_16', 'emb_17', 'emb_18', 'emb_19', 'emb_20', 'emb_21', 'emb_22', 'emb_23', 'emb_24', 'emb_25', 'emb_26', 'emb_27', 'emb_28', 'emb_29', 'emb_30', 'emb_31']. Note that there were extra inputs: ['29', '27', '8', '6', '16', '30', '24', '31', '10', '20', '22', '11', '5', '28', '17', '9', '14', '15', '26', '7', '18', '23', '19', '12', '21', '13', '0', '2', '3', '1', '25', '4']

[2025-06-06T15:44:34.885+0000] {train_deep_model_dag.py:29} ERROR - ❌ Subprozess-Fehler (exit code 1): python /opt/***/src/models/predict_best_model.py
[2025-06-06T15:44:34.886+0000] {train_deep_model_dag.py:32} ERROR - ❌ Subprozess-Ausnahme: Command '['python', '/opt/***/src/models/predict_best_model.py']' returned non-zero exit status 1.
[2025-06-06T15:44:34.886+0000] {taskinstance.py:2698} ERROR - Task failed with exception
Traceback (most recent call last):
  File "/home/airflow/.local/lib/python3.10/site-packages/airflow/models/taskinstance.py", line 433, in _execute_task
    result = execute_callable(context=context, **execute_callable_kwargs)
  File "/home/airflow/.local/lib/python3.10/site-packages/airflow/operators/python.py", line 199, in execute
    return_value = self.execute_callable()
  File "/home/airflow/.local/lib/python3.10/site-packages/airflow/operators/python.py", line 216, in execute_callable
    return self.python_callable(*self.op_args, **self.op_kwargs)
  File "/opt/airflow/dags/train_deep_model_dag.py", line 71, in run_predict_best_model
    run_and_log(["python", "/opt/airflow/src/models/predict_best_model.py"])
  File "/opt/airflow/dags/train_deep_model_dag.py", line 30, in run_and_log
    raise subprocess.CalledProcessError(result.returncode, command)
subprocess.CalledProcessError: Command '['python', '/opt/airflow/src/models/predict_best_model.py']' returned non-zero exit status 1.
[2025-06-06T15:44:34.895+0000] {taskinstance.py:1138} INFO - Marking task as UP_FOR_RETRY. dag_id=deep_models_pipeline, task_id=predict_best_model, execution_date=20250606T154108, start_date=20250606T154427, end_date=20250606T154434
[2025-06-06T15:44:34.904+0000] {standard_task_runner.py:107} ERROR - Failed to execute job 2197 for task predict_best_model (Command '['python', '/opt/airflow/src/models/predict_best_model.py']' returned non-zero exit status 1.; 778)
[2025-06-06T15:44:34.937+0000] {local_task_job_runner.py:234} INFO - Task exited with return code 1
[2025-06-06T15:44:34.949+0000] {taskinstance.py:3280} INFO - 0 downstream tasks scheduled from follow-on schedule check
